Workbook

Sheet Détail Modèle Hydrologique
A1: RÉSULTATS DÉTAILLÉS DU MODÈLE HYDROLOGIQUE
A2: Dossiers sources : resultats_normal & resultats_humide | Capacité de rétention du bassin : 1 500 m³
A4: SCÉNARIO : SOL NORMAL (Dossier: resultats_normal)
A5: Période | B5: Avec Infiltration (m³) | C5: Sans Infiltration (m³) | D5: Volume Infiltré (m³) | E5: Taux d'Infiltration (%) | F5: Statut Bassin (1 500 m³) | G5: Marge / Débordement (m³)
A6: T2 | B6: 38.7 | C6: 180.9 | D6: =C6-B6 -> 142.2 | E6: =(C6-B6)/C6 -> 0.78606965 | F6: Conforme | G6: =1500-B6 -> 1461.3
A7: T5 | B7: 95.2 | C7: 278.4 | D7: =C7-B7 -> 183.2 | E7: =(C7-B7)/C7 -> 0.65804598 | F7: Conforme | G7: =1500-B7 -> 1404.8
A8: T10 | B8: 166.9 | C8: 388.9 | D8: =C8-B8 -> 222 | E8: =(C8-B8)/C8 -> 0.57084083 | F8: Conforme | G8: =1500-B8 -> 1333.1
A9: T20 | B9: 262.2 | C9: 546.3 | D9: =C9-B9 -> 284.1 | E9: =(C9-B9)/C9 -> 0.52004393 | F9: Conforme | G9: =1500-B9 -> 1237.8
A10: T50 | B10: 438.6 | C10: 825.2 | D10: =C10-B10 -> 386.6 | E10: =(C10-B10)/C10 -> 0.46849249 | F10: Conforme | G10: =1500-B10 -> 1061.4
A11: T100 | B11: 614.3 | C11: 1078.8 | D11: =C11-B11 -> 464.5 | E11: =(C11-B11)/C11 -> 0.430571 | F11: Conforme | G11: =1500-B11 -> 885.7
A13: SCÉNARIO : SOL HUMIDE (Dossier: resultats_humide)
A14: Période | B14: Avec Infiltration (m³) | C14: Sans Infiltration (m³) | D14: Volume Infiltré (m³) | E14: Taux d'Infiltration (%) | F14: Statut Bassin (1 500 m³) | G14: Marge / Débordement (m³)
A15: T2 | B15: 226 | C15: 409.5 | D15: =C15-B15 -> 183.5 | E15: =(C15-B15)/C15 -> 0.44810745 | F15: Conforme | G15: =1500-B15 -> 1274
A16: T5 | B16: 737.4 | C16: 943.3 | D16: =C16-B16 -> 205.9 | E16: =(C16-B16)/C16 -> 0.21827626 | F16: Conforme | G16: =1500-B16 -> 762.6
A17: T10 | B17: 1230 | C17: 1399.3 | D17: =C17-B17 -> 169.3 | E17: =(C17-B17)/C17 -> 0.12098907 | F17: Conforme | G17: =1500-B17 -> 270
A18: T20 | B18: 1785.6 | C18: 1892.7 | D18: =C18-B18 -> 107.1 | E18: =(C18-B18)/C18 -> 0.05658583 | F18: DÉBORDEMENT (+285.6 m³) | G18: =1500-B18 -> -285.6
A19: T50 | B19: 2591.7 | C19: 2624 | D19: =C19-B19 -> 32.3 | E19: =(C19-B19)/C19 -> 0.012309451 | F19: DÉBORDEMENT (+1 091.7 m³) | G19: =1500-B19 -> -1091.7
A20: T100 | B20: 3191.5 | C20: 3213 | D20: =C20-B20 -> 21.5 | E20: =(C20-B20)/C20 -> 0.0066915655 | F20: DÉBORDEMENT (+1 691.5 m³) | G20: =1500-B20 -> -1691.5

Sheet Détail Calculs Excel (OCS)
A1: DÉTAIL DES CALCULS EXCEL PAR TYPE D'OCCUPATION DU SOL (VERSION CORRIGÉE)
A2: Matrices détaillées de ruissellement par sous-bassin (B, C, D) et coefficients de ruissellement corrigés (QP2 à QP100)
A4: SCÉNARIO : SOL NORMAL | H4: SCÉNARIO : SOL HUMIDE
A6: QP2 (m³) | B6: B | C6: C | D6: D | E6: Volume Total (m³) | F6: Coeff. Ruiss. Corrigé (%) | H6: QP2 (m³) | I6: B | J6: C | K6: D | L6: Volume Total (m³) | M6: Coeff. Ruiss. Corrigé (%)
A7: Caillouteux | B7: 33.46 | C7: 52.14 | D7: 11.63 | H7: Caillouteux | I7: 33.46 | J7: 52.14 | K7: 11.63
A8: Foret | B8: 0 | C8: 0 | D8: 0 | H8: Foret | I8: 0 | J8: 0 | K8: 0
A9: Herbe | B9: 0 | C9: 0 | D9: 0 | H9: Herbe | I9: 0 | J9: 0 | K9: 0
A10: Vignes | B10: 0 | C10: 0 | D10: 0.01 | H10: Vignes | I10: 1.28 | J10: 147.89 | K10: 88.24
A11: Zones urbanisees | B11: 0 | C11: 68.08 | D11: 15.7 | E11: =SUM(B7:D11) -> 181.02 | F11: 0.025 | H11: Zones urbanisees | I11: 0 | J11: 68.08 | K11: 15.7 | L11: =SUM(I7:K11) -> 418.42 | M11: 0.0577
A14: QP5 (m³) | B14: B | C14: C | D14: D | E14: Volume Total (m³) | F14: Coeff. Ruiss. Corrigé (%) | H14: QP5 (m³) | I14: B | J14: C | K14: D | L14: Volume Total (m³) | M14: Coeff. Ruiss. Corrigé (%)
A15: Caillouteux | B15: 47.97 | C15: 74.75 | D15: 16.67 | H15: Caillouteux | I15: 47.97 | J15: 74.75 | K15: 16.67
A16: Foret | B16: 0 | C16: 0 | D16: 0 | H16: Foret | I16: 0 | J16: 0 | K16: 0
A17: Herbe | B17: 0 | C17: 0 | D17: 0 | H17: Herbe | I17: 0 | J17: 0 | K17: 0
A18: Vignes | B18: 0 | C18: 0.15 | D18: 19.13 | H18: Vignes | I18: 21.24 | J18: 488.59 | K18: 209.38
A19: Zones urbanisees | B19: 0 | C19: 97.59 | D19: 22.51 | E19: =SUM(B15:D19) -> 278.77 | F19: 0.0282 | H19: Zones urbanisees | I19: 0 | J19: 97.59 | K19: 22.51 | L19: =SUM(I15:K19) -> 978.7 | M19: 0.0988
A22: QP10 (m³) | B22: B | C22: C | D22: D | E22: Volume Total (m³) | F22: Coeff. Ruiss. Corrigé (%) | H22: QP10 (m³) | I22: B | J22: C | K22: D | L22: Volume Total (m³) | M22: Coeff. Ruiss. Corrigé (%)
A23: Caillouteux | B23: 57.62 | C23: 89.79 | D23: 20.03 | H23: Caillouteux | I23: 57.62 | J23: 89.79 | K23: 20.03
A24: Foret | B24: 0 | C24: 0 | D24: 0 | H24: Foret | I24: 0 | J24: 0 | K24: 0
A25: Herbe | B25: 0 | C25: 0 | D25: 0 | H25: Herbe | I25: 0 | J25: 0 | K25: 0
A26: Vignes | B26: 0 | C26: 30.31 | D26: 49.83 | H26: Vignes | I26: 45.91 | J26: 794.96 | K26: 307.49
A27: Zones urbanisees | B27: 0 | C27: 117.24 | D27: 27.04 | E27: =SUM(B23:D27) -> 391.86 | F27: 0.0336 | H27: Zones urbanisees | I27: 0 | J27: 117.24 | K27: 27.04 | L27: =SUM(I23:K27) -> 1460.08 | M27: 0.1252
A30: QP20 (m³) | B30: B | C30: C | D30: D | E30: Volume Total (m³) | F30: Coeff. Ruiss. Corrigé (%) | H30: QP20 (m³) | I30: B | J30: C | K30: D | L30: Volume Total (m³) | M30: Coeff. Ruiss. Corrigé (%)
A31: Caillouteux | B31: 66.91 | C31: 104.26 | D31: 23.25 | H31: Caillouteux | I31: 66.91 | J31: 104.26 | K31: 23.25
A32: Foret | B32: 0 | C32: 0 | D32: 0 | H32: Foret | I32: 0 | J32: 0 | K32: 0
A33: Herbe | B33: 0 | C33: 0 | D33: 0 | H33: Herbe | I33: 0 | J33: 0 | K33: 0
A34: Vignes | B34: 0 | C34: 105.03 | D34: 90.81 | H34: Vignes | I34: 76.82 | J34: 1137.31 | K34: 411.84
A35: Zones urbanisees | B35: 0 | C35: 136.13 | D35: 31.4 | E35: =SUM(B31:D35) -> 557.79 | F35: 0.0418 | H35: Zones urbanisees | I35: 0 | J35: 136.13 | K35: 31.4 | L35: =SUM(I31:K35) -> 1987.92 | M35: 0.149
A38: QP50 (m³) | B38: B | C38: C | D38: D | E38: Volume Total (m³) | F38: Coeff. Ruiss. Corrigé (%) | H38: QP50 (m³) | I38: B | J38: C | K38: D | L38: Volume Total (m³) | M38: Coeff. Ruiss. Corrigé (%)
A39: Caillouteux | B39: 78.94 | C39: 123.02 | D39: 27.44 | H39: Caillouteux | I39: 78.94 | J39: 123.02 | K39: 27.44
A40: Foret | B40: 0 | C40: 0 | D40: 0 | H40: Foret | I40: 0 | J40: 0 | K40: 0
A41: Herbe | B41: 0 | C41: 0.13 | D41: 1.17 | H41: Herbe | I41: 0 | J41: 0.13 | K41: 1.17
A42: Vignes | B42: 0.09 | C42: 261.49 | D42: 158.52 | H42: Vignes | I42: 125.9 | J42: 1638.89 | K42: 558.81
A43: Zones urbanisees | B43: 0 | C43: 160.62 | D43: 37.05 | E43: =SUM(B39:D43) -> 848.47 | F43: 0.0546 | H43: Zones urbanisees | I43: 0 | J43: 160.62 | K43: 37.05 | L43: =SUM(I39:K43) -> 2751.97 | M43: 0.1773
A46: QP100 (m³) | B46: B | C46: C | D46: D | E46: Volume Total (m³) | F46: Coeff. Ruiss. Corrigé (%) | H46: QP100 (m³) | I46: B | J46: C | K46: D | L46: Volume Total (m³) | M46: Coeff. Ruiss. Corrigé (%)
A47: Caillouteux | B47: 87.98 | C47: 137.1 | D47: 30.58 | H47: Caillouteux | I47: 87.98 | J47: 137.1 | K47: 30.58
A48: Foret | B48: 0 | C48: 0 | D48: 0 | H48: Foret | I48: 0 | J48: 0 | K48: 0.06
A49: Herbe | B49: 0 | C49: 4.4 | D49: 3.56 | H49: Herbe | I49: 0 | J49: 4.4 | K49: 3.56
A50: Vignes | B50: 3.1 | C50: 418.59 | D50: 218.8 | H50: Vignes | I50: 168.54 | J50: 2051.09 | K50: 676.1
A51: Zones urbanisees | B51: 0 | C51: 179 | D51: 41.29 | E51: =SUM(B47:D51) -> 1124.4 | F51: 0.0655 | H51: Zones urbanisees | I51: 0 | J51: 179 | K51: 41.29 | L51: =SUM(I47:K51) -> 3379.7 | M51: 0.1969
A54: SYNTHÈSE DU RUISSELLEMENT PAR OCCUPATION DU SOL (OCS) DU PAS DE TEMPS QP2 À QP100
...

Sheet Comparatif Synthétique
A1: TABLEAU COMPARATIF : MODÈLE HYDROLOGIQUE vs CALCULS EXCEL (VERSION CORRIGÉE)
A2: Analyse comparative des volumes ruisselés (m³), coefficients de ruissellement corrigés et dimensionnement du bassin (1 500 m³)
A4: SCÉNARIO 1 : SOL NORMAL
A5: Période de retour | B5: Calcul Excel (m³) | C5: Modèle Sans Infiltration (m³) | D5: Modèle Avec Infiltration (m³) | E5: Écart Excel vs Modèle Brut (m³) | F5: Écart Excel vs Modèle Brut (%) | G5: Coeff. Ruiss. Corrigé (%) | H5: Statut Bassin (1 500 m³)
A6: T2 | B6: 181 | C6: 180.9 | D6: 38.7 | E6: =B6-C6 -> 0.1 | F6: =(B6-C6)/C6 -> 0.0005527916 | G6: 0.025 | H6: Conforme
A7: T5 | B7: 278.8 | C7: 278.4 | D7: 95.2 | E7: =B7-C7 -> 0.4 | F7: =(B7-C7)/C7 -> 0.0014367816 | G7: 0.0282 | H7: Conforme
A8: T10 | B8: 391.9 | C8: 388.9 | D8: 166.9 | E8: =B8-C8 -> 3 | F8: =(B8-C8)/C8 -> 0.0077140653 | G8: 0.0336 | H8: Conforme
A9: T20 | B9: 557.8 | C9: 546.3 | D9: 262.2 | E9: =B9-C9 -> 11.5 | F9: =(B9-C9)/C9 -> 0.021050705 | G9: 0.0418 | H9: Conforme
A10: T50 | B10: 848.5 | C10: 825.2 | D10: 438.6 | E10: =B10-C10 -> 23.3 | F10: =(B10-C10)/C10 -> 0.028235579 | G10: 0.0546 | H10: Conforme
A11: T100 | B11: 1124.4 | C11: 1078.8 | D11: 614.3 | E11: =B11-C11 -> 45.6 | F11: =(B11-C11)/C11 -> 0.042269188 | G11: 0.0655 | H11: Conforme
A13: SCÉNARIO 2 : SOL HUMIDE
A14: Période de retour | B14: Calcul Excel (m³) | C14: Modèle Sans Infiltration (m³) | D14: Modèle Avec Infiltration (m³) | E14: Écart Excel vs Modèle Brut (m³) | F14: Écart Excel vs Modèle Brut (%) | G14: Coeff. Ruiss. Corrigé (%) | H14: Statut Bassin (1 500 m³)
A15: T2 | B15: 418.4 | C15: 409.5 | D15: 226 | E15: =B15-C15 -> 8.9 | F15: =(B15-C15)/C15 -> 0.021733822 | G15: 0.0577 | H15: Conforme
A16: T5 | B16: 978.7 | C16: 943.3 | D16: 737.4 | E16: =B16-C16 -> 35.4 | F16: =(B16-C16)/C16 -> 0.037527828 | G16: 0.0988 | H16: Conforme
A17: T10 | B17: 1460.1 | C17: 1399.3 | D17: 1230 | E17: =B17-C17 -> 60.8 | F17: =(B17-C17)/C17 -> 0.043450297 | G17: 0.1252 | H17: Conforme
A18: T20 | B18: 1987.9 | C18: 1892.7 | D18: 1785.6 | E18: =B18-C18 -> 95.2 | F18: =(B18-C18)/C18 -> 0.050298515 | G18: 0.149 | H18: DÉBORDEMENT (+285.6 m³)
A19: T50 | B19: 2752 | C19: 2624 | D19: 2591.7 | E19: =B19-C19 -> 128 | F19: =(B19-C19)/C19 -> 0.048780488 | G19: 0.1773 | H19: DÉBORDEMENT (+1 091.7 m³)
A20: T100 | B20: 3379.7 | C20: 3213 | D20: 3191.5 | E20: =B20-C20 -> 166.7 | F20: =(B20-C20)/C20 -> 0.051882975 | G20: 0.1969 | H20: DÉBORDEMENT (+1 691.5 m³)
A22: SCÉNARIO COMPARATIF : IMPACT DE LA SATURATION DU SOL (SOL HUMIDE vs SOL NORMAL)
A23: Période | B23: Excel Sol Normal (m³) | C23: Excel Sol Humide (m³) | D23: Variation Volume Excel (%) | E23: CR Corrigé Normal (%) | F23: CR Corrigé Humide (%) | G23: Multiplicateur de Ruissellement
A24: T2 | B24: =B6 -> 181 | C24: =B15 -> 418.4 | D24: =(C24-B24)/B24 -> 1.3116022 | E24: =G6 -> 0.025 | F24: =G15 -> 0.0577 | G24: =C24/B24 -> 2.3116022
A25: T5 | B25: =B7 -> 278.8 | C25: =B16 -> 978.7 | D25: =(C25-B25)/B25 -> 2.5104017 | E25: =G7 -> 0.0282 | F25: =G16 -> 0.0988 | G25: =C25/B25 -> 3.5104017
A26: T10 | B26: =B8 -> 391.9 | C26: =B17 -> 1460.1 | D26: =(C26-B26)/B26 -> 2.7256953 | E26: =G8 -> 0.0336 | F26: =G17 -> 0.1252 | G26: =C26/B26 -> 3.7256953
A27: T20 | B27: =B9 -> 557.8 | C27: =B18 -> 1987.9 | D27: =(C27-B27)/B27 -> 2.5638222 | E27: =G9 -> 0.0418 | F27: =G18 -> 0.149 | G27: =C27/B27 -> 3.5638222
A28: T50 | B28: =B10 -> 848.5 | C28: =B19 -> 2752 | D28: =(C28-B28)/B28 -> 2.2433707 | E28: =G10 -> 0.0546 | F28: =G19 -> 0.1773 | G28: =C28/B28 -> 3.2433707
A29: T100 | B29: =B11 -> 1124.4 | C29: =B20 -> 3379.7 | D29: =(C29-B29)/B29 -> 2.0057809 | E29: =G11 -> 0.0655 | F29: =G20 -> 0.1969 | G29: =C29/B29 -> 3.0057809

Sheet Analyse Sols SCS (B-C-D)
A1: ANALYSE HYDROLOGIQUE PAR NATURE DU SOL (GROUPES SCS B, C, D)
A2: Caractérisation des sols, production spécifique au m² (m³/ha), bilan des contributions au bassin
A4: 1. CARACTÉRISATION DES GROUPES HYDROLOGIQUES DE SOLS (GHS SCS)
A5: Nature du Sol (GHS) | B5: Description pédologique & hydrologique | C5: Superficie (m²) | D5: Superficie (ha) | E5: Part du Bassin (%) | F5: CN moyen pondéré (Normal) | G5: S moyen Normal (mm) | H5: Ia Normal (mm) | I5: CN moyen pondéré (Humide) | J5: S moyen Humide (mm) | K5: Ia Humide (mm)
A6: Sol B | B6: Infiltration modérée (sols limoneux profonds) | C6: 144314.9 | D6: =C6/10000 -> 14.43149 | E6: =C6/$C$9 -> 0.32158585 | F6: 44.2 | G6: =(25400/F6)-254 -> 320.66063 | H6: =0.2*G6 -> 64.132127 | I6: 57.2 | J6: =(25400/I6)-254 -> 190.05594 | K6: =0.2*J6 -> 38.011189
A7: Sol C | B7: Faible infiltration (sols argilo-limoneux) | C7: 247702.6 | D7: =C7/10000 -> 24.77026 | E7: =C7/$C$9 -> 0.55197109 | F7: 68.7 | G7: =(25400/F7)-254 -> 115.72344 | H7: =0.2*G7 -> 23.144687 | I7: 80 | J7: =(25400/I7)-254 -> 63.5 | K7: =0.2*J7 -> 12.7
A8: Sol D | B8: Très faible perméabilité / lourd (argiles compactes) | C8: 56742.6 | D8: =C8/10000 -> 5.67426 | E8: =C8/$C$9 -> 0.12644306 | F8: 74.1 | G8: =(25400/F8)-254 -> 88.780027 | H8: =0.2*G8 -> 17.756005 | I8: 84.2 | J8: =(25400/I8)-254 -> 47.662708 | K8: =0.2*J8 -> 9.5325416
A9: TOTAL / MOYENNE | B9: Bassin Versant Global | C9: =SUM(C6:C8) -> 448760.1 | D9: =SUM(D6:D8) -> 44.87601 | E9: =SUM(E6:E8) -> 1 | F9: =(F6*C6+F7*C7+F8*C8)/C9 -> 61.503939 | G9: =(25400/F9)-254 -> 158.98168 | H9: =0.2*G9 -> 31.796336 | I9: =(I6*C6+I7*C7+I8*C8)/C9 -> 73.198903 | J9: =(25400/I9)-254 -> 92.999734 | K9: =0.2*J9 -> 18.599947
A12: 2. VOLUMES RUISSÉLÉS ET CONTRIBUTION RELATIVE AU BASSIN (SCÉNARIO SOL HUMIDE)
A13: Nature du Sol (GHS) | B13: QP2 (m³) | C13: Part QP2 (%) | D13: QP5 (m³) | E13: Part QP5 (%) | F13: QP10 (m³) | G13: Part QP10 (%) | H13: QP20 (m³) | I13: Part QP20 (%) | J13: QP50 (m³) | K13: Part QP50 (%) | L13: QP100 (m³) | M13: Part QP100 (%)
A14: Sol B | B14: =SUM('Détail Calculs Excel (OCS)'!I7:I11) -> 34.74 | C14: =B14/B$17 -> 0.083026624 | D14: =SUM('Détail Calculs Excel (OCS)'!I15:I19) -> 69.21 | E14: =D14/D$17 -> 0.070716256 | F14: =SUM('Détail Calculs Excel (OCS)'!I23:I27) -> 103.53 | G14: =F14/F$17 -> 0.070907074 | H14: =SUM('Détail Calculs Excel (OCS)'!I31:I35) -> 143.73 | I14: =H14/H$17 -> 0.072301702 | J14: =SUM('Détail Calculs Excel (OCS)'!I39:I43) -> 204.84 | K14: =J14/J$17 -> 0.074433951 | L14: =SUM('Détail Calculs Excel (OCS)'!I47:I51) -> 256.52 | M14: =L14/L$17 -> 0.075900228
A15: Sol C | B15: =SUM('Détail Calculs Excel (OCS)'!J7:J11) -> 268.11 | C15: =B15/B$17 -> 0.64076765 | D15: =SUM('Détail Calculs Excel (OCS)'!J15:J19) -> 660.93 | E15: =D15/D$17 -> 0.67531419 | F15: =SUM('Détail Calculs Excel (OCS)'!J23:J27) -> 1001.99 | G15: =F15/F$17 -> 0.68625692 | H15: =SUM('Détail Calculs Excel (OCS)'!J31:J35) -> 1377.7 | I15: =H15/H$17 -> 0.69303594 | J15: =SUM('Détail Calculs Excel (OCS)'!J39:J43) -> 1922.66 | K15: =J15/J$17 -> 0.6986486 | L15: =SUM('Détail Calculs Excel (OCS)'!J47:J51) -> 2371.59 | M15: =L15/L$17 -> 0.70171613
A16: Sol D | B16: =SUM('Détail Calculs Excel (OCS)'!K7:K11) -> 115.57 | C16: =B16/B$17 -> 0.27620573 | D16: =SUM('Détail Calculs Excel (OCS)'!K15:K19) -> 248.56 | E16: =D16/D$17 -> 0.25396955 | F16: =SUM('Détail Calculs Excel (OCS)'!K23:K27) -> 354.56 | G16: =F16/F$17 -> 0.24283601 | H16: =SUM('Détail Calculs Excel (OCS)'!K31:K35) -> 466.49 | I16: =H16/H$17 -> 0.23466236 | J16: =SUM('Détail Calculs Excel (OCS)'!K39:K43) -> 624.47 | K16: =J16/J$17 -> 0.22691744 | L16: =SUM('Détail Calculs Excel (OCS)'!K47:K51) -> 751.59 | M16: =L16/L$17 -> 0.22238364
A17: TOTAL BASSIN | B17: =SUM(B14:B16) -> 418.42 | C17: 100.0% | D17: =SUM(D14:D16) -> 978.7 | E17: 100.0% | F17: =SUM(F14:F16) -> 1460.08 | G17: 100.0% | H17: =SUM(H14:H16) -> 1987.92 | I17: 100.0% | J17: =SUM(J14:J16) -> 2751.97 | K17: 100.0% | L17: =SUM(L14:L16) -> 3379.7 | M17: 100.0%
A20: 3. RUISSELLEMENT SPÉCIFIQUE PAR HECTARE (m³/ha) - VULNÉRABILITÉ COMPARÉE
A21: Nature du Sol (GHS) | B21: Superficie (ha) | C21: QP2 (m³/ha) | D21: QP5 (m³/ha) | E21: QP10 (m³/ha) | F21: QP20 (m³/ha) | G21: QP50 (m³/ha) | H21: QP100 (m³/ha) | I21: Ratio de Vulnérabilité (vs Sol B à QP100)
A22: Sol B | B22: =D6 -> 14.43149 | C22: =B14/$B22 -> 2.4072358 | D22: =D14/$B22 -> 4.7957626 | E22: =F14/$B22 -> 7.1738954 | F22: =H14/$B22 -> 9.9594706 | G22: =J14/$B22 -> 14.193961 | H22: =L14/$B22 -> 17.775018 | I22: =H22/$H$22 -> 1
A23: Sol C | B23: =D7 -> 24.77026 | C23: =B15/$B23 -> 10.823867 | D23: =D15/$B23 -> 26.682401 | E23: =F15/$B23 -> 40.451332 | F23: =H15/$B23 -> 55.619117 | G23: =J15/$B23 -> 77.619694 | H23: =L15/$B23 -> 95.743444 | I23: =H23/$H$22 -> 5.3864048
A24: Sol D | B24: =D8 -> 5.67426 | C24: =B16/$B24 -> 20.367414 | D24: =D16/$B24 -> 43.804831 | E24: =F16/$B24 -> 62.485681 | F24: =H16/$B24 -> 82.211601 | G24: =J16/$B24 -> 110.05312 | H24: =L16/$B24 -> 132.45604 | I24: =H24/$H$22 -> 7.4518088
A25: MOYENNE BASSIN | B25: =D9 -> 44.87601 | C25: =B17/$B25 -> 9.3239127 | D25: =D17/$B25 -> 21.80898 | E25: =F17/$B25 -> 32.535869 | F25: =H17/$B25 -> 44.298056 | G25: =J17/$B25 -> 61.323857 | H25: =L17/$B25 -> 75.311954 | I25: =H25/$H$22 -> 4.2369551

Sheet Analyse Pratique viticole
A1: ANALYSE HYDROLOGIQUE PAR PRATIQUES VITICOLE
A2: Analyse des pratiques viticole
A5: 1. IMPACT DES PRATIQUES DE GESTION DU SOL DANS LES VIGNES (EDS_2) PAR CLASSE DE SOL
A6: Pratique Viticole (Mode de conduite) | B6: Sol B (m²) | C6: Sol C (m²) | D6: Sol D (m²) | E6: Total Général (m²) | F6: Total Général (ha) | G6: Part du Vignoble (%) | H6: CN AMC-III (Sol B / C / D) (Référence) | I6: QP10 (m³) | J6: QP100 (m³) | K6: CN AMC-III (Sol B / C / D) Modifier | L6: QP10 (m³) | M6: QP100 (m³)
A7: Vignes en sol nu / Travail du sol ('0') | B7: 5291.3 | C7: 26667.3 | D7: 16125.2 | E7: =SUM(B7:D7) -> 48083.8 | F7: =E7/10000 -> 4.80838 | G7: =E7/$E$10 -> 0.18003048 | H7: 78 - 84 - 88 | I7: 227.24 | J7: 554.14 | K7: 82 - 88 - 92 | L7: 368.55 | M7: 773.25
A8: Vignes enherbées 1 rang sur 2 ('1/2') | B8: 5899.6 | C8: 104195.1 | D8: 27522.1 | E8: =SUM(B8:D8) -> 137616.8 | F8: =E8/10000 -> 13.76168 | G8: =E8/$E$10 -> 0.51525084 | H8: 78 - 84 - 88 | I8: 623.88 | J8: 1549.25 | K8: 78 - 84 - 88 | L8: 623.88 | M8: 1549.25
A9: Vignes enherbées intégrales ('1/1') | B9: 16976.4 | C9: 62580.2 | D9: 1829.8 | E9: =SUM(B9:D9) -> 81386.4 | F9: =E9/10000 -> 8.13864 | G9: =E9/$E$10 -> 0.30471869 | H9: 78 - 84 - 88 | I9: 297.24 | J9: 792.34 | K9: 70 - 76 - 80 | L9: 75.42 | M9: 351.23
A10: TOTAL VIGNOBLE | B10: =SUM(B7:B9) -> 28167.3 | C10: =SUM(C7:C9) -> 193442.6 | D10: =SUM(D7:D9) -> 45477.1 | E10: =SUM(E7:E9) -> 267087 | F10: =E10/10000 -> 26.7087 | G10: 100.0% | H10: - | I10: =SUM(I7:I9) -> 1148.36 | J10: =SUM(J7:J9) -> 2895.73 | K10: - | L10: =SUM(L7:L9) -> 1067.85 | M10: =SUM(M7:M9) -> 2673.73

Sheet Analyse Fuite 
A1: ANALYSE DE SENSIBILITÉ : IMPACT DE L'INFILTRATION ET CAPACITÉ DU BASSIN (1 500 m³)
A3: 1. MODÈLE (FORTAN) - SANS Infiltration - SOL NORMAL
A4: Période | B4: Volume Entrant (m³) | C4: Vol. évacué à 1 L/s/ha (m³) | D4: Volume à stocker à 1 L/s/ha (m³) | E4: Statut Bassin 1 L/s/ha (1 500 m³) | F4: Vol. évacué à 3 L/s/ha (m³) | G4: Volume à stocker à 3 L/s/ha (m³) | H4: Statut Bassin 3 L/s/ha (1 500 m³)
A5: T2 | B5: 180.9 | C5: =$K$15*3600 -> 161.568 | D5: 18.9 | E5: Conforme | F5: =$K$16*3600 -> 484.704 | G5: 0 | H5: Conforme | J5: Hectar du bassin versant : | K5: 44.88
A6: T5 | B6: 278.4 | C6: =$K$15*3600 -> 161.568 | D6: 116.4 | E6: Conforme | F6: =$K$16*3600 -> 484.704 | G6: 0 | H6: Conforme
A7: T10 | B7: 388.9 | C7: =$K$15*3600 -> 161.568 | D7: 226.9 | E7: Conforme | F7: =$K$16*3600 -> 484.704 | G7: 0 | H7: Conforme | J7: Calcul du débit continue de l'ouvrage
A8: T20 | B8: 546.3 | C8: =$K$15*3600 -> 161.568 | D8: 384.3 | E8: Conforme | F8: =$K$16*3600 -> 484.704 | G8: 61.3 | H8: Conforme | J8: 1 L/s/ha : | K8: =K5*1 -> 44.88
A9: T50 | B9: 825.2 | C9: =$K$15*3600 -> 161.568 | D9: 663.2 | E9: Conforme | F9: =$K$16*3600 -> 484.704 | G9: 340.2 | H9: Conforme | J9: 3L /s/ ha : | K9: =K5*3 -> 134.64
A10: T100 | B10: 1078.8 | C10: =$K$15*3600 -> 161.568 | D10: 916.8 | E10: Conforme | F10: =$K$16*3600 -> 484.704 | G10: 593.8 | H10: Conforme
A12: 2. MODÈLE (FORTAN) - AVEC Infiltration - SOL NORMAL
A13: Période | B13: Volume Entrant (m³) | C13: Vol. évacué à 1 L/s/ha (m³) | D13: Volume à stocker à 1 L/s/ha (m³) | E13: Statut Bassin 1 L/s/ha (1 500 m³) | F13: Vol. évacué à 3 L/s/ha (m³) | G13: Volume à stocker à 3 L/s/ha (m³) | H13: Statut Bassin 3 L/s/ha (1 500 m³)
A14: T2 | B14: 38.7 | C14: =$K$15*3600 -> 161.568 | D14: 0 | E14: Conforme | F14: =$K$16*3600 -> 484.704 | G14: 0 | H14: Conforme | J14: Conversion mètres cubes par seconde :
A15: T5 | B15: 95.2 | C15: =$K$15*3600 -> 161.568 | D15: 0 | E15: Conforme | F15: =$K$16*3600 -> 484.704 | G15: 0 | H15: Conforme | J15: 1 L/s/ha : | K15: =K8/1000 -> 0.04488
A16: T10 | B16: 166.9 | C16: =$K$15*3600 -> 161.568 | D16: =B16-C16 -> 5.332 | E16: Conforme | F16: =$K$16*3600 -> 484.704 | G16: 0 | H16: Conforme | J16: 3L /s/ ha : | K16: =K9/1000 -> 0.13464
A17: T20 | B17: 262.2 | C17: =$K$15*3600 -> 161.568 | D17: =B17-C17 -> 100.632 | E17: Conforme | F17: =$K$16*3600 -> 484.704 | G17: 0 | H17: Conforme
A18: T50 | B18: 438.6 | C18: =$K$15*3600 -> 161.568 | D18: =B18-C18 -> 277.032 | E18: Conforme | F18: =$K$16*3600 -> 484.704 | G18: 0 | H18: Conforme
A19: T100 | B19: 614.3 | C19: =$K$15*3600 -> 161.568 | D19: =B19-C19 -> 452.732 | E19: Conforme | F19: =$K$16*3600 -> 484.704 | G19: =B19-F19 -> 129.596 | H19: Conforme
A21: 3. MODÈLE (FORTAN) - SANS Infiltration - SOL HUMIDE
A22: Période | B22: Volume Entrant (m³) | C22: Vol. évacué à 1 L/s/ha (m³) | D22: Volume à stocker à 1 L/s/ha (m³) | E22: Statut Bassin 1 L/s/ha (1 500 m³) | F22: Vol. évacué à 3 L/s/ha (m³) | G22: Volume à stocker à 3 L/s/ha (m³) | H22: Statut Bassin 3 L/s/ha (1 500 m³)
A23: T2 | B23: 409.5 | C23: =$K$15*3600 -> 161.568 | D23: =B23-C23 -> 247.932 | E23: Conforme | F23: =$K$16*3600 -> 484.704 | G23: 0 | H23: Conforme
A24: T5 | B24: 943.3 | C24: =$K$15*3600 -> 161.568 | D24: =B24-C24 -> 781.732 | E24: Conforme | F24: =$K$16*3600 -> 484.704 | G24: =B24-F24 -> 458.596 | H24: Conforme
A25: T10 | B25: 1399.3 | C25: =$K$15*3600 -> 161.568 | D25: =B25-C25 -> 1237.732 | E25: Conforme | F25: =$K$16*3600 -> 484.704 | G25: =B25-F25 -> 914.596 | H25: Conforme
A26: T20 | B26: 1892.7 | C26: =$K$15*3600 -> 161.568 | D26: =B26-C26 -> 1731.132 | E26: Débordement | F26: =$K$16*3600 -> 484.704 | G26: =B26-F26 -> 1407.996 | H26: Conforme
A27: T50 | B27: 2624 | C27: =$K$15*3600 -> 161.568 | D27: =B27-C27 -> 2462.432 | E27: Débordement | F27: =$K$16*3600 -> 484.704 | G27: =B27-F27 -> 2139.296 | H27: Débordement
A28: T100 | B28: 3213 | C28: =$K$15*3600 -> 161.568 | D28: =B28-C28 -> 3051.432 | E28: Débordement | F28: =$K$16*3600 -> 484.704 | G28: =B28-F28 -> 2728.296 | H28: Débordement
A30: 4. MODÈLE (FORTAN) - AVEC Infiltration - SOL HUMIDE
A31: Période | B31: Volume Entrant (m³) | C31: Vol. évacué à 1 L/s/ha (m³) | D31: Volume à stocker à 1 L/s/ha (m³) | E31: Statut Bassin 1 L/s/ha (1 500 m³) | F31: Vol. évacué à 3 L/s/ha (m³) | G31: Volume à stocker à 3 L/s/ha (m³) | H31: Statut Bassin 3 L/s/ha (1 500 m³)
A32: T2 | B32: 226 | C32: =$K$15*3600 -> 161.568 | D32: =B32-C32 -> 64.432 | E32: Conforme | F32: =$K$16*3600 -> 484.704 | G32: 0 | H32: Conforme
A33: T5 | B33: 737.4 | C33: =$K$15*3600 -> 161.568 | D33: =B33-C33 -> 575.832 | E33: Conforme | F33: =$K$16*3600 -> 484.704 | G33: =B33-F33 -> 252.696 | H33: Conforme
A34: T10 | B34: 1230 | C34: =$K$15*3600 -> 161.568 | D34: =B34-C34 -> 1068.432 | E34: Conforme | F34: =$K$16*3600 -> 484.704 | G34: =B34-F34 -> 745.296 | H34: Conforme
A35: T20 | B35: 1785.6 | C35: =$K$15*3600 -> 161.568 | D35: =B35-C35 -> 1624.032 | E35: Débordement | F35: =$K$16*3600 -> 484.704 | G35: =B35-F35 -> 1300.896 | H35: Conforme
A36: T50 | B36: 2591.7 | C36: =$K$15*3600 -> 161.568 | D36: =B36-C36 -> 2430.132 | E36: Débordement | F36: =$K$16*3600 -> 484.704 | G36: =B36-F36 -> 2106.996 | H36: Débordement
A37: T100 | B37: 3191.5 | C37: =$K$15*3600 -> 161.568 | D37: =B37-C37 -> 3029.932 | E37: Débordement | F37: =$K$16*3600 -> 484.704 | G37: =B37-F37 -> 2706.796 | H37: Débordement
A39: 5. CALCUL EXCEL - SOL NORMAL (Méthode sans infiltration)
A40: Période | B40: Volume Entrant (m³) | C40: Vol. évacué à 1 L/s/ha (m³) | D40: Volume à stocker à 1 L/s/ha (m³) | E40: Statut Bassin 1 L/s/ha (1 500 m³) | F40: Vol. évacué à 3 L/s/ha (m³) | G40: Volume à stocker à 3 L/s/ha (m³) | H40: Statut Bassin 3 L/s/ha (1 500 m³)
A41: T2 | B41: 181 | C41: =$K$15*3600 -> 161.568 | D41: =B41-C41 -> 19.432 | E41: Conforme | F41: =$K$16*3600 -> 484.704 | G41: 0 | H41: Conforme
A42: T5 | B42: 278.8 | C42: =$K$15*3600 -> 161.568 | D42: =B42-C42 -> 117.232 | E42: Conforme | F42: =$K$16*3600 -> 484.704 | G42: 0 | H42: Conforme
A43: T10 | B43: 391.9 | C43: =$K$15*3600 -> 161.568 | D43: =B43-C43 -> 230.332 | E43: Conforme | F43: =$K$16*3600 -> 484.704 | G43: 0 | H43: Conforme
A44: T20 | B44: 557.8 | C44: =$K$15*3600 -> 161.568 | D44: =B44-C44 -> 396.232 | E44: Conforme | F44: =$K$16*3600 -> 484.704 | G44: =B44-F44 -> 73.096 | H44: Conforme
A45: T50 | B45: 848.5 | C45: =$K$15*3600 -> 161.568 | D45: =B45-C45 -> 686.932 | E45: Conforme | F45: =$K$16*3600 -> 484.704 | G45: =B45-F45 -> 363.796 | H45: Conforme
...

Sheet Graphiques Mémoire
A3: 1. COMPARATIF CALCULS EXCEL vs MODÈLE FORTRAN (m³) | G3: 2. RISQUE DE DÉBORDEMENT DU BASSIN (CAPACITÉ 1 500 m³) Modèle FORTRAN
A4: Période | B4: Excel AMC-II (m³) | C4: Fortran AMC-II (m³) | D4: Excel AMC-III (m³) | E4: Fortran AMC-III (m³) | G4: Période | H4: Volume de ruissellement AMC-II (m³) | I4: Volume de ruissellement AMC-III (m³) | J4: Capacité Bassin (m³)
A5: T2 | B5: ='Comparatif Synthétique'!B6 -> 181 | C5: ='Comparatif Synthétique'!C6 -> 180.9 | D5: ='Comparatif Synthétique'!B15 -> 418.4 | E5: ='Comparatif Synthétique'!C15 -> 409.5 | G5: T2 | H5: ='Comparatif Synthétique'!D6 -> 38.7 | I5: ='Comparatif Synthétique'!D15 -> 226 | J5: 1500
A6: T5 | B6: ='Comparatif Synthétique'!B7 -> 278.8 | C6: ='Comparatif Synthétique'!C7 -> 278.4 | D6: ='Comparatif Synthétique'!B16 -> 978.7 | E6: ='Comparatif Synthétique'!C16 -> 943.3 | G6: T5 | H6: ='Comparatif Synthétique'!D7 -> 95.2 | I6: ='Comparatif Synthétique'!D16 -> 737.4 | J6: 1500
A7: T10 | B7: ='Comparatif Synthétique'!B8 -> 391.9 | C7: ='Comparatif Synthétique'!C8 -> 388.9 | D7: ='Comparatif Synthétique'!B17 -> 1460.1 | E7: ='Comparatif Synthétique'!C17 -> 1399.3 | G7: T10 | H7: ='Comparatif Synthétique'!D8 -> 166.9 | I7: ='Comparatif Synthétique'!D17 -> 1230 | J7: 1500
A8: T20 | B8: ='Comparatif Synthétique'!B9 -> 557.8 | C8: ='Comparatif Synthétique'!C9 -> 546.3 | D8: ='Comparatif Synthétique'!B18 -> 1987.9 | E8: ='Comparatif Synthétique'!C18 -> 1892.7 | G8: T20 | H8: ='Comparatif Synthétique'!D9 -> 262.2 | I8: ='Comparatif Synthétique'!D18 -> 1785.6 | J8: 1500
A9: T50 | B9: ='Comparatif Synthétique'!B10 -> 848.5 | C9: ='Comparatif Synthétique'!C10 -> 825.2 | D9: ='Comparatif Synthétique'!B19 -> 2752 | E9: ='Comparatif Synthétique'!C19 -> 2624 | G9: T50 | H9: ='Comparatif Synthétique'!D10 -> 438.6 | I9: ='Comparatif Synthétique'!D19 -> 2591.7 | J9: 1500
A10: T100 | B10: ='Comparatif Synthétique'!B11 -> 1124.4 | C10: ='Comparatif Synthétique'!C11 -> 1078.8 | D10: ='Comparatif Synthétique'!B20 -> 3379.7 | E10: ='Comparatif Synthétique'!C20 -> 3213 | G10: T100 | H10: ='Comparatif Synthétique'!D11 -> 614.3 | I10: ='Comparatif Synthétique'!D20 -> 3191.5 | J10: 1500
A12: 4. COMPARAISON DÉBIT DE FUITE : VOLUMES À STOCKER (m³) (Fortran avec infiltration)
A13: Période | B13: AMC-II - 1 L/s/ha (m³) | C13: AMC-II - 3 L/s/ha (m³) | D13: AMC-III - 1 L/s/ha (m³) | E13: AMC-III - 3 L/s/ha (m³) | F13: Capacité Bassin (m³) | G13: 3. LEVIER DE L'ENHERBEMENT VITICOLE (SOLUTIONS FONDÉES SUR LA NATURE - QP10)
A14: ='Analyse Fuite '!A14 -> T2 | B14: ='Analyse Fuite '!D14 -> 0 | C14: ='Analyse Fuite '!G14 -> 0 | D14: ='Analyse Fuite '!D32 -> 64.432 | E14: ='Analyse Fuite '!G32 -> 0 | F14: 1500 | G14: Mode de Conduite Viticole | H14: Superficie (ha) | I14: QP10 CN Référence (m³) | J14: QP10 CN Modifier (m³) | K14: Variation Ruissellement (%)
A15: ='Analyse Fuite '!A15 -> T5 | B15: ='Analyse Fuite '!D15 -> 0 | C15: ='Analyse Fuite '!G15 -> 0 | D15: ='Analyse Fuite '!D33 -> 575.832 | E15: ='Analyse Fuite '!G33 -> 252.696 | F15: 1500 | G15: ='Analyse Pratique viticole'!A7 -> Vignes en sol nu / Travail du sol ('0') | H15: ='Analyse Pratique viticole'!F7 -> 4.80838 | I15: ='Analyse Pratique viticole'!I7 -> 227.24 | J15: ='Analyse Pratique viticole'!L7 -> 368.55 | K15: =(J15-I15)/I15 -> 0.62185355
A16: ='Analyse Fuite '!A16 -> T10 | B16: ='Analyse Fuite '!D16 -> 5.332 | C16: ='Analyse Fuite '!G16 -> 0 | D16: ='Analyse Fuite '!D34 -> 1068.432 | E16: ='Analyse Fuite '!G34 -> 745.296 | F16: 1500 | G16: ='Analyse Pratique viticole'!A8 -> Vignes enherbées 1 rang sur 2 ('1/2') | H16: ='Analyse Pratique viticole'!F8 -> 13.76168 | I16: ='Analyse Pratique viticole'!I8 -> 623.88 | J16: ='Analyse Pratique viticole'!L8 -> 623.88 | K16: =(J16-I16)/I16 -> 0
A17: ='Analyse Fuite '!A17 -> T20 | B17: ='Analyse Fuite '!D17 -> 100.632 | C17: ='Analyse Fuite '!G17 -> 0 | D17: ='Analyse Fuite '!D35 -> 1624.032 | E17: ='Analyse Fuite '!G35 -> 1300.896 | F17: 1500 | G17: ='Analyse Pratique viticole'!A9 -> Vignes enherbées intégrales ('1/1') | H17: ='Analyse Pratique viticole'!F9 -> 8.13864 | I17: ='Analyse Pratique viticole'!I9 -> 297.24 | J17: ='Analyse Pratique viticole'!L9 -> 75.42 | K17: =(J17-I17)/I17 -> -0.74626564
A18: ='Analyse Fuite '!A18 -> T50 | B18: ='Analyse Fuite '!D18 -> 277.032 | C18: ='Analyse Fuite '!G18 -> 0 | D18: ='Analyse Fuite '!D36 -> 2430.132 | E18: ='Analyse Fuite '!G36 -> 2106.996 | F18: 1500 | G18: ='Analyse Pratique viticole'!A10 -> TOTAL VIGNOBLE | H18: ='Analyse Pratique viticole'!F10 -> 26.7087 | I18: ='Analyse Pratique viticole'!I10 -> 1148.36 | J18: ='Analyse Pratique viticole'!L10 -> 1067.85 | K18: =(J18-I18)/I18 -> -0.070108677
A19: ='Analyse Fuite '!A19 -> T100 | B19: ='Analyse Fuite '!D19 -> 452.732 | C19: ='Analyse Fuite '!G19 -> 129.596 | D19: ='Analyse Fuite '!D37 -> 3029.932 | E19: ='Analyse Fuite '!G37 -> 2706.796 | F19: 1500
A21: 5. COMPARAISON DÉBIT DE FUITE : VOLUMES À STOCKER (m³) (Fortran sans infiltration) | G21: 2.5. RISQUE DE DÉBORDEMENT DU BASSIN (CAPACITÉ 1 500 m³) Calcul Excel
A22: Période | B22: AMC-II - 1 L/s/ha (m³) | C22: AMC-II - 3 L/s/ha (m³) | D22: AMC-III - 1 L/s/ha (m³) | E22: AMC-III - 3 L/s/ha (m³) | F22: Capacité Bassin (m³) | G22: Période | H22: Volume de ruissellement AMC-II (m³) | I22: Volume de ruissellement AMC-III (m³) | J22: Capacité Bassin (m³)
A23: ='Analyse Fuite '!A23 -> T2 | B23: ='Analyse Fuite '!D5 -> 18.9 | C23: ='Analyse Fuite '!G5 -> 0 | D23: ='Analyse Fuite '!D23 -> 247.932 | E23: ='Analyse Fuite '!G23 -> 0 | F23: 1500 | G23: T2 | H23: 181 | I23: 418.4 | J23: 1500
A24: ='Analyse Fuite '!A24 -> T5 | B24: ='Analyse Fuite '!D6 -> 116.4 | C24: ='Analyse Fuite '!G6 -> 0 | D24: ='Analyse Fuite '!D24 -> 781.732 | E24: ='Analyse Fuite '!G24 -> 458.596 | F24: 1500 | G24: T5 | H24: 278.8 | I24: 978.7 | J24: 1500
A25: ='Analyse Fuite '!A25 -> T10 | B25: ='Analyse Fuite '!D7 -> 226.9 | C25: ='Analyse Fuite '!G7 -> 0 | D25: ='Analyse Fuite '!D25 -> 1237.732 | E25: ='Analyse Fuite '!G25 -> 914.596 | F25: 1500 | G25: T10 | H25: 391.9 | I25: 1460.1 | J25: 1500
A26: ='Analyse Fuite '!A26 -> T20 | B26: ='Analyse Fuite '!D8 -> 384.3 | C26: ='Analyse Fuite '!G8 -> 61.3 | D26: ='Analyse Fuite '!D26 -> 1731.132 | E26: ='Analyse Fuite '!G26 -> 1407.996 | F26: 1500 | G26: T20 | H26: 557.8 | I26: 1987.9 | J26: 1500
A27: ='Analyse Fuite '!A27 -> T50 | B27: ='Analyse Fuite '!D9 -> 663.2 | C27: ='Analyse Fuite '!G9 -> 340.2 | D27: ='Analyse Fuite '!D27 -> 2462.432 | E27: ='Analyse Fuite '!G27 -> 2139.296 | F27: 1500 | G27: T50 | H27: 848.5 | I27: 2752 | J27: 1500
A28: ='Analyse Fuite '!A28 -> T100 | B28: ='Analyse Fuite '!D10 -> 916.8 | C28: ='Analyse Fuite '!G10 -> 593.8 | D28: ='Analyse Fuite '!D28 -> 3051.432 | E28: ='Analyse Fuite '!G28 -> 2728.296 | F28: 1500 | G28: T100 | H28: 1124.4 | I28: 3379.7 | J28: 1500
A30: 6. COMPARAISON DÉBIT DE FUITE : VOLUMES À STOCKER (m³) (Excel) | G30: 7. ANALYSE DE VULNERABILITE PAR L'OCS
A31: Période | B31: AMC-II - 1 L/s/ha (m³) | C31: AMC-II - 3 L/s/ha (m³) | D31: AMC-III - 1 L/s/ha (m³) | E31: AMC-III - 3 L/s/ha (m³) | F31: Capacité Bassin (m³) | G31: Type d'OCS | H31: QP2 (m³) | I31: QP5 (m³) | J31: QP10 (m³) | K31: QP20 (m³) | L31: QP50 (m³) | M31: QP100 (m³) | N31: Total Cumulé | O31: Part (%)
A32: ='Analyse Fuite '!A32 -> T2 | B32: ='Analyse Fuite '!D41 -> 19.432 | C32: ='Analyse Fuite '!G41 -> 0 | D32: ='Analyse Fuite '!D50 -> 256.832 | E32: ='Analyse Fuite '!G50 -> 0 | F32: 1500 | G32: Caillouteux | H32: 97.2 | I32: 139.4 | J32: 167.4 | K32: 194.4 | L32: 229.4 | M32: 255.7 | N32: 1 083,5 m³ | O32: 9,9 %
A33: ='Analyse Fuite '!A33 -> T5 | B33: ='Analyse Fuite '!D42 -> 117.232 | C33: ='Analyse Fuite '!G42 -> 0 | D33: ='Analyse Fuite '!D51 -> 817.132 | E33: ='Analyse Fuite '!G51 -> 493.996 | F33: 1500 | G33: Forêt | H33: 0 | I33: 0 | J33: 0 | K33: 0 | L33: 0 | M33: 0.1 | N33: 0,1 m³ | O33: 0,0 %
A34: ='Analyse Fuite '!A34 -> T10 | B34: ='Analyse Fuite '!D43 -> 230.332 | C34: ='Analyse Fuite '!G43 -> 0 | D34: ='Analyse Fuite '!D52 -> 1298.532 | E34: ='Analyse Fuite '!G52 -> 975.396 | F34: 1500 | G34: Herbe | H34: 0 | I34: 0 | J34: 0 | K34: 0 | L34: 1.3 | M34: 8 | N34: 9,3 m³ | O34: 0,1 %
A35: ='Analyse Fuite '!A35 -> T20 | B35: ='Analyse Fuite '!D44 -> 396.232 | C35: ='Analyse Fuite '!G44 -> 73.096 | D35: ='Analyse Fuite '!D53 -> 1826.332 | E35: ='Analyse Fuite '!G53 -> 1503.196 | F35: 1500 | G35: Vignes | H35: 237.4 | I35: 719.2 | J35: 1148.4 | K35: 1626 | L35: 2323.6 | M35: 2895.7 | N35: 8950.3 | O35: 0.815
A36: ='Analyse Fuite '!A36 -> T50 | B36: ='Analyse Fuite '!D45 -> 686.932 | C36: ='Analyse Fuite '!G45 -> 363.796 | D36: ='Analyse Fuite '!D54 -> 2590.432 | E36: ='Analyse Fuite '!G54 -> 2267.296 | F36: 1500 | G36: Zones urbanisées | H36: 83.8 | I36: 120.1 | J36: 144.3 | K36: 167.5 | L36: 197.7 | M36: 220.3 | N36: 933.7 | O36: 0.085
A37: ='Analyse Fuite '!A37 -> T100 | B37: ='Analyse Fuite '!D46 -> 962.832 | C37: ='Analyse Fuite '!G46 -> 639.696 | D37: ='Analyse Fuite '!D55 -> 3218.132 | E37: ='Analyse Fuite '!G55 -> 2894.996 | F37: 1500 | G37: Total | H37: 418.4 | I37: 978.7 | J37: 1460.1 | K37: 1987.9 | L37: 2752 | M37: 3379.7 | N37: 10976.8 | O37: 1
